<?xml version="1.0" encoding="utf-8"?>
<!-- This URDF was automatically created by SolidWorks to URDF Exporter! Originally created by Stephen Brawner (brawner@gmail.com) 
     Commit Version: 1.6.0-4-g7f85cfe  Build Version: 1.6.7995.38578
     For more information, please see http://wiki.ros.org/sw_urdf_exporter -->
<robot name="puma_model" xmlns:xacro="http://ros.org/wiki/xacro">
  <xacro:include filename="$(find puma_model)/urdf/puma_model.gazebo.xacro"/>
  
  <link
    name="base_link">
    <inertial>
      <origin
        xyz="0.016651799447873 2.50054494388419E-07 0.3700954993344"
        rpy="0 0 0" />
      <mass
        value="141.871222119219" />
      <inertia
        ixx="3.58592238244372"
        ixy="-7.70630741878065E-07"
        ixz="1.05770487262547"
        iyy="17.6914485683265"
        iyz="8.25132789133817E-06"
        izz="18.0504461411871" />
    </inertial>
    <visual>
      <origin
        xyz="0 0 0"
        rpy="0 0 0" />
      <geometry>
        <mesh
          filename="package://puma_model/meshes/base_link.STL" />
      </geometry>
      <material
        name="">
        <color
          rgba="0.988235294117647 0.737254901960784 0.517647058823529 1" />
      </material>
    </visual>
    <collision>
      <origin
        xyz="0 0 0"
        rpy="0 0 0" />
      <geometry>
        <mesh
          filename="package://puma_model/meshes/base_link.STL" />
      </geometry>
    </collision>
  </link>
  <link
    name="dir_right_link">
    <inertial>
      <origin
        xyz="3.33066907387547E-16 -0.047021105109952 0"
        rpy="0 0 0" />
      <mass
        value="0.450226734865359" />
      <inertia
        ixx="0.000452930170196998"
        ixy="-2.08351206347224E-20"
        ixz="-1.93425232022472E-21"
        iyy="0.000507367249025541"
        iyz="3.95205740912683E-20"
        izz="0.000460794419124139" />
    </inertial>
    <visual>
      <origin
        xyz="0 0 0"
        rpy="0 0 0" />
      <geometry>
        <mesh
          filename="package://puma_model/meshes/dir_right_link.STL" />
      </geometry>
      <material
        name="">
        <color
          rgba="0.823529411764706 0.823529411764706 0.823529411764706 1" />
      </material>
    </visual>
    <collision>
      <origin
        xyz="0 0 0"
        rpy="0 0 0" />
      <geometry>
        <mesh
          filename="package://puma_model/meshes/dir_right_link.STL" />
      </geometry>
    </collision>
  </link>
  <joint
    name="dir_right_joint"
    type="continuous">
    <origin
      xyz="0.52673 -0.353 0.265"
      rpy="0 0 0" />
    <parent
      link="base_link" />
    <child
      link="dir_right_link" />
    <axis
      xyz="0 0 1" />

  </joint>
  <link
    name="wheel_right_front_link">
    <inertial>
      <origin
        xyz="0 -1.11022302462516E-16 0.0700000000000001"
        rpy="0 0 0" />
      <mass
        value="33.8332405777372" />
      <inertia
        ixx="0.663166940004142"
        ixy="1.74598601904134E-32"
        ixz="4.51486827425246E-17"
        iyy="0.663166940004142"
        iyz="1.07735398960113E-17"
        izz="1.19194782788173" />
    </inertial>
    <visual>
      <origin
        xyz="0 0 0"
        rpy="0 0 0" />
      <geometry>
        <mesh
          filename="package://puma_model/meshes/wheel_right_front_link.STL" />
      </geometry>
      <material
        name="">
        <color
          rgba="1 0.752941176470588 0.752941176470588 1" />
      </material>
    </visual>
    <collision>
      <origin
        xyz="0 0 0"
        rpy="0 0 0" />
      <geometry>
        <mesh
          filename="package://puma_model/meshes/wheel_right_front_link.STL" />
      </geometry>
    </collision>
  </link>
  <joint
    name="wheel_right_front_joint"
    type="continuous">
    <origin
      xyz="0 -0.078 0"
      rpy="1.5708 0 0" />
    <parent
      link="dir_right_link" />
    <child
      link="wheel_right_front_link" />
    <axis
      xyz="0 0 -1" />
    <dynamics
      friction="1" />
  </joint>
  <link
    name="dir_left_link">
    <inertial>
      <origin
        xyz="4.44089209850063E-16 0.0470211051099522 1.11022302462516E-16"
        rpy="0 0 0" />
      <mass
        value="0.450226734865359" />
      <inertia
        ixx="0.000452930170196997"
        ixy="-7.29252817374884E-21"
        ixz="-1.63781186538735E-21"
        iyy="0.00050736724902554"
        iyz="1.60159589115665E-20"
        izz="0.000460794419124138" />
    </inertial>
    <visual>
      <origin
        xyz="0 0 0"
        rpy="0 0 0" />
      <geometry>
        <mesh
          filename="package://puma_model/meshes/dir_left_link.STL" />
      </geometry>
      <material
        name="">
        <color
          rgba="0.823529411764706 0.823529411764706 0.823529411764706 1" />
      </material>
    </visual>
    <collision>
      <origin
        xyz="0 0 0"
        rpy="0 0 0" />
      <geometry>
        <mesh
          filename="package://puma_model/meshes/dir_left_link.STL" />
      </geometry>
    </collision>
  </link>
  <joint
    name="dir_left_joint"
    type="continuous">
    <origin
      xyz="0.52673 0.353 0.265"
      rpy="0 0 0" />
    <parent
      link="base_link" />
    <child
      link="dir_left_link" />
    <axis
      xyz="0 0 1" />
  </joint>
  <link
    name="wheel_left_front_link">
    <inertial>
      <origin
        xyz="0 2.22044604925031E-16 0.0700000000000002"
        rpy="0 0 0" />
      <mass
        value="33.8332405777372" />
      <inertia
        ixx="0.663166940004142"
        ixy="4.56652860083993E-32"
        ixz="-3.47625364951278E-17"
        iyy="0.663166940004142"
        iyz="-9.24811874513642E-18"
        izz="1.19194782788173" />
    </inertial>
    <visual>
      <origin
        xyz="0 0 0"
        rpy="0 0 0" />
      <geometry>
        <mesh
          filename="package://puma_model/meshes/wheel_left_front_link.STL" />
      </geometry>
      <material
        name="">
        <color
          rgba="1 0.752941176470588 0.752941176470588 1" />
      </material>
    </visual>
    <collision>
      <origin
        xyz="0 0 0"
        rpy="0 0 0" />
      <geometry>
        <mesh
          filename="package://puma_model/meshes/wheel_left_front_link.STL" />
      </geometry>
    </collision>
  </link>
  <joint
    name="wheel_left_front_joint"
    type="continuous">
    <origin
      xyz="0 0.078 0"
      rpy="1.5708 0 -3.1416" />
    <parent
      link="dir_left_link" />
    <child
      link="wheel_left_front_link" />
    <axis
      xyz="0 0 -1" />
    <dynamics
      friction="1" />
  </joint>
  <link
    name="wheel_right_back_link">
    <inertial>
      <origin
        xyz="1.55431223447522E-15 -1.55431223447522E-15 0.1"
        rpy="0 0 0" />
      <mass
        value="42.8421975932662" />
      <inertia
        ixx="0.843504879614984"
        ixy="-9.59503304028305E-33"
        ixz="6.01287397790472E-17"
        iyy="0.843504879614984"
        iyz="-2.42963471245841E-16"
        izz="1.34196583325215" />
    </inertial>
    <visual>
      <origin
        xyz="0 0 0"
        rpy="0 0 0" />
      <geometry>
        <mesh
          filename="package://puma_model/meshes/wheel_right_back_link.STL" />
      </geometry>
      <material
        name="">
        <color
          rgba="0.666666666666667 0.666666666666667 0.666666666666667 1" />
      </material>
    </visual>
    <collision>
      <origin
        xyz="0 0 0"
        rpy="0 0 0" />
      <geometry>
        <mesh
          filename="package://puma_model/meshes/wheel_right_back_link.STL" />
      </geometry>
    </collision>
  </link>
  <joint
    name="wheel_right_back_joint"
    type="continuous">
    <origin
      xyz="-0.52327 -0.275 0.25"
      rpy="1.5708 0 0" />
    <parent
      link="base_link" />
    <child
      link="wheel_right_back_link" />
    <axis
      xyz="0 0 -1" />
    <dynamics
      friction="1" />
  </joint>
  <link
    name="wheel_left_back_link">
    <inertial>
      <origin
        xyz="3.33066907387547E-16 -2.22044604925031E-16 0.0999999999999999"
        rpy="0 0 0" />
      <mass
        value="42.8421975932662" />
      <inertia
        ixx="0.843504879614984"
        ixy="-5.97993043604167E-33"
        ixz="-3.69567293190445E-18"
        iyy="0.843504879614984"
        iyz="1.50156913172873E-17"
        izz="1.34196583325215" />
    </inertial>
    <visual>
      <origin
        xyz="0 0 0"
        rpy="0 0 0" />
      <geometry>
        <mesh
          filename="package://puma_model/meshes/wheel_left_back_link.STL" />
      </geometry>
      <material
        name="">
        <color
          rgba="0.666666666666667 0.666666666666667 0.666666666666667 1" />
      </material>
    </visual>
    <collision>
      <origin
        xyz="0 0 0"
        rpy="0 0 0" />
      <geometry>
        <mesh
          filename="package://puma_model/meshes/wheel_left_back_link.STL" />
      </geometry>
    </collision>
  </link>
  <joint
    name="wheel_left_back_joint"
    type="continuous">
    <origin
      xyz="-0.52327 0.275 0.25"
      rpy="-1.5708 0 0" />
    <parent
      link="base_link" />
    <child
      link="wheel_left_back_link" />
    <axis
      xyz="0 0 -1" />
    <dynamics
      friction="1" />
  </joint>
  <link
    name="base_component_link">
    <inertial>
      <origin
        xyz="0 -1.38777878078145E-17 0"
        rpy="0 0 0" />
      <mass
        value="26.928" />
      <inertia
        ixx="0.399432"
        ixy="5.25749814054658E-17"
        ixz="-1.90310730137829E-18"
        iyy="0.368016"
        iyz="5.64237288394698E-34"
        izz="0.5502288" />
    </inertial>
    <visual>
      <origin
        xyz="0 0 0"
        rpy="0 0 0" />
      <geometry>
        <mesh
          filename="package://puma_model/meshes/base_component_link.STL" />
      </geometry>
      <material
        name="">
        <color
          rgba="1 0.752941176470588 1 1" />
      </material>
    </visual>
    <collision>
      <origin
        xyz="0 0 0"
        rpy="0 0 0" />
      <geometry>
        <mesh
          filename="package://puma_model/meshes/base_component_link.STL" />
      </geometry>
    </collision>
  </link>
  <joint
    name="base_component_joint"
    type="fixed">
    <origin
      xyz="0.076727 0 0.63"
      rpy="0 0 0" />
    <parent
      link="base_link" />
    <child
      link="base_component_link" />
    <axis
      xyz="0 0 0" />
  </joint>
  <link
    name="gps_link">
    <inertial>
      <origin
        xyz="0 0 -0.00999999999999995"
        rpy="0 0 0" />
      <mass
        value="0.1" />
      <inertia
        ixx="8.66666666666667E-05"
        ixy="1.76566841298316E-20"
        ixz="1.00796920723262E-21"
        iyy="2.41666666666667E-05"
        iyz="-4.3548787261501E-22"
        izz="0.000104166666666667" />
    </inertial>
    <visual>
      <origin
        xyz="0 0 0"
        rpy="0 0 0" />
      <geometry>
        <mesh
          filename="package://puma_model/meshes/gps_link.STL" />
      </geometry>
      <material
        name="">
        <color
          rgba="0.623529411764706 1 0.76078431372549 1" />
      </material>
    </visual>
    <collision>
      <origin
        xyz="0 0 0"
        rpy="0 0 0" />
      <geometry>
        <mesh
          filename="package://puma_model/meshes/gps_link.STL" />
      </geometry>
    </collision>
  </link>
  <joint
    name="gps_joint"
    type="fixed">
    <origin
      xyz="0.22173 0 0.76"
      rpy="0 0 0" />
    <parent
      link="base_link" />
    <child
      link="gps_link" />
    <axis
      xyz="0 0 0" />
  </joint>
  <link
    name="imu1_link">
    <inertial>
      <origin
        xyz="0.01 0 0"
        rpy="0 0 0" />
      <mass
        value="0.1" />
      <inertia
        ixx="0.000104166666666667"
        ixy="1.57322252736699E-21"
        ixz="2.01593841446523E-21"
        iyy="8.6666666666667E-05"
        iyz="-1.03902708196528E-20"
        izz="2.41666666666667E-05" />
    </inertial>
    <visual>
      <origin
        xyz="0 0 0"
        rpy="0 0 0" />
      <geometry>
        <mesh
          filename="package://puma_model/meshes/imu1_link.STL" />
      </geometry>
      <material
        name="">
        <color
          rgba="0.792156862745098 0.819607843137255 0.933333333333333 1" />
      </material>
    </visual>
    <collision>
      <origin
        xyz="0 0 0"
        rpy="0 0 0" />
      <geometry>
        <mesh
          filename="package://puma_model/meshes/imu1_link.STL" />
      </geometry>
    </collision>
  </link>
  <joint
    name="imu1_joint"
    type="fixed">
    <origin
      xyz="-0.69327 0 0.57"
      rpy="0 0 0" />
    <parent
      link="base_link" />
    <child
      link="imu1_link" />
    <axis
      xyz="0 0 0" />
  </joint>
  <link
    name="imu2_link">
    <inertial>
      <origin
        xyz="-0.01 0 0"
        rpy="0 0 0" />
      <mass
        value="0.1" />
      <inertia
        ixx="0.000104166666666667"
        ixy="-5.26402742286973E-22"
        ixz="2.3628831096606E-21"
        iyy="8.66666666666669E-05"
        iyz="6.6181507612138E-22"
        izz="2.41666666666667E-05" />
    </inertial>
    <visual>
      <origin
        xyz="0 0 0"
        rpy="0 0 0" />
      <geometry>
        <mesh
          filename="package://puma_model/meshes/imu2_link.STL" />
      </geometry>
      <material
        name="">
        <color
          rgba="0.792156862745098 0.819607843137255 0.933333333333333 1" />
      </material>
    </visual>
    <collision>
      <origin
        xyz="0 0 0"
        rpy="0 0 0" />
      <geometry>
        <mesh
          filename="package://puma_model/meshes/imu2_link.STL" />
      </geometry>
    </collision>
  </link>
  <joint
    name="imu2_joint"
    type="fixed">
    <origin
      xyz="0.59673 0 0.37"
      rpy="0 0 0" />
    <parent
      link="base_link" />
    <child
      link="imu2_link" />
    <axis
      xyz="0 0 0" />
  </joint>
  
</robot>