<?xml version="1.0" encoding="utf-8"?>
<!-- This URDF was automatically created by SolidWorks to URDF Exporter! Originally created by Stephen Brawner (brawner@gmail.com) 
     Commit Version: 1.6.0-4-g7f85cfe  Build Version: 1.6.7995.38578
     For more information, please see http://wiki.ros.org/sw_urdf_exporter -->
<robot name="puma_model" xmlns:xacro="http://ros.org/wiki/xacro">
  <xacro:include filename="$(find puma_model_camera)/urdf/puma_model.gazebo.xacro"/>
  
  <xacro:arg name="use_nominal_extrinsics" default="true"/>
  <xacro:arg name="add_plug" default="false" />
  <xacro:arg name="name" default="camera" />
  <xacro:arg name="topics_ns" default="camera" />
  <xacro:arg name="publish_pointcloud" default="true" />
  <xacro:include filename="$(find puma_model_camera)/urdf/d455.urdf.xacro" />

  
  <link
    name="base_link">
    <inertial>
      <origin
        xyz="0.016828 2.5244E-07 0.36947"
        rpy="0 0 0" />
      <mass
        value="154.38" />
      <inertia
        ixx="3.8644"
        ixy="-9.5023E-07"
        ixz="1.1536"
        iyy="22.232"
        iyz="9.0131E-06"
        izz="22.651" />
    </inertial>
    <visual>
      <origin
        xyz="0 0 0"
        rpy="0 0 0" />
      <geometry>
        <mesh
          filename="package://puma_model_camera/meshes/base_link.STL" />
      </geometry>
      <material
        name="">
        <color
          rgba="0.98824 0.73725 0.51765 1" />
      </material>
    </visual>
    <collision>
      <origin
        xyz="0 0 0"
        rpy="0 0 0" />
      <geometry>
        <mesh
          filename="package://puma_model_camera/meshes/base_link.STL" />
      </geometry>
    </collision>
  </link>
  <link
    name="dir_right_link">
    <inertial>
      <origin
        xyz="-2.2204E-16 -0.029478 0"
        rpy="0 0 0" />
      <mass
        value="0.21461" />
      <inertia
        ixx="0.00016179"
        ixy="-1.2567E-20"
        ixz="-1.7214E-21"
        iyy="0.00021284"
        iyz="1.1854E-20"
        izz="0.00016965" />
    </inertial>
    <visual>
      <origin
        xyz="0 0 0"
        rpy="0 0 0" />
      <geometry>
        <mesh
          filename="package://puma_model_camera/meshes/dir_right_link.STL" />
      </geometry>
      <material
        name="">
        <color
          rgba="0.82353 0.82353 0.82353 1" />
      </material>
    </visual>
    <collision>
      <origin
        xyz="0 0 0"
        rpy="0 0 0" />
      <geometry>
        <mesh
          filename="package://puma_model_camera/meshes/dir_right_link.STL" />
      </geometry>
    </collision>
  </link>
  <joint
    name="dir_right_joint"
    type="continuous">
    <origin
      xyz="0.57673 -0.337 0.265"
      rpy="0 0 0" />
    <parent
      link="base_link" />
    <child
      link="dir_right_link" />
    <axis
      xyz="0 0 1" />

  </joint>
  <link
    name="wheel_right_front_link">
    <inertial>
      <origin
        xyz="0 1.1102E-16 0.07"
        rpy="0 0 0" />
      <mass
        value="33.833" />
      <inertia
        ixx="0.66317"
        ixy="1.746E-32"
        ixz="4.5149E-17"
        iyy="0.66317"
        iyz="1.0774E-17"
        izz="1.1919" />
    </inertial>
    <visual>
      <origin
        xyz="0 0 0"
        rpy="0 0 0" />
      <geometry>
        <mesh
          filename="package://puma_model_camera/meshes/wheel_right_front_link.STL" />
      </geometry>
      <material
        name="">
        <color
          rgba="1 0.75294 0.75294 1" />
      </material>
    </visual>
    <collision>
      <origin
        xyz="0 0 0"
        rpy="0 0 0" />
      <geometry>
        <mesh
          filename="package://puma_model_camera/meshes/wheel_right_front_link.STL" />
      </geometry>
    </collision>
  </link>
  <joint
    name="wheel_right_front_joint"
    type="continuous">
    <origin
      xyz="0 -0.048 0"
      rpy="1.5708 0 0" />
    <parent
      link="dir_right_link" />
    <child
      link="wheel_right_front_link" />
    <axis
      xyz="0 0 -1" />

    <dynamics
      friction="1" />
  </joint>
  <link
    name="dir_left_link">
    <inertial>
      <origin
        xyz="0 0.0294777193153578 1.11022302462516E-16"
        rpy="0 0 0" />
      <mass
        value="0.214607285846125" />
      <inertia
        ixx="0.000161787233745492"
        ixy="1.7829483231954E-21"
        ixz="-2.5363205724219E-21"
        iyy="0.000212842937751498"
        iyz="3.89270928347116E-20"
        izz="0.000169651482672632" />
    </inertial>
    <visual>
      <origin
        xyz="0 0 0"
        rpy="0 0 0" />
      <geometry>
        <mesh
          filename="package://puma_model_camera/meshes/dir_left_link.STL" />
      </geometry>
      <material
        name="">
        <color
          rgba="0.823529411764706 0.823529411764706 0.823529411764706 1" />
      </material>
    </visual>
    <collision>
      <origin
        xyz="0 0 0"
        rpy="0 0 0" />
      <geometry>
        <mesh
          filename="package://example_simulation_camera/meshes/dir_left_link.STL" />
      </geometry>
    </collision>
  </link>
  <joint
    name="dir_left_joint"
    type="continuous">
    <origin
      xyz="0.576729916214884 0.337 0.265"
      rpy="0 0 0" />
    <parent
      link="base_link" />
    <child
      link="dir_left_link" />
    <axis
      xyz="0 0 1" />

  </joint>
  <link
    name="wheel_left_front_link">
    <inertial>
      <origin
        xyz="0 0 0.0699999999999999"
        rpy="0 0 0" />
      <mass
        value="33.8332405777372" />
      <inertia
        ixx="0.663166940004142"
        ixy="3.62902943280336E-32"
        ixz="-3.47625364951278E-17"
        iyy="0.663166940004142"
        iyz="1.01566182105979E-18"
        izz="1.19194782788173" />
    </inertial>
    <visual>
      <origin
        xyz="0 0 0"
        rpy="0 0 0" />
      <geometry>
        <mesh
          filename="package://puma_model_camera/meshes/wheel_left_front_link.STL" />
      </geometry>
      <material
        name="">
        <color
          rgba="1 0.752941176470588 0.752941176470588 1" />
      </material>
    </visual>
    <collision>
      <origin
        xyz="0 0 0"
        rpy="0 0 0" />
      <geometry>
        <mesh
          filename="package://puma_model_camera/meshes/wheel_left_front_link.STL" />
      </geometry>
    </collision>
  </link>
  <joint
    name="wheel_left_front_joint"
    type="continuous">
    <origin
      xyz="0 0.048 0"
      rpy="1.5708 0 -3.1416" />
    <parent
      link="dir_left_link" />
    <child
      link="wheel_left_front_link" />
    <axis
      xyz="0 0 -1" />

    <dynamics
      friction="1" />
  </joint>
  <link
    name="wheel_right_back_link">
    <inertial>
      <origin
        xyz="0 1.11022302462516E-16 0.1"
        rpy="0 0 0" />
      <mass
        value="42.8421975932662" />
      <inertia
        ixx="0.843504879614984"
        ixy="-2.17897005442215E-32"
        ixz="6.01287397790473E-17"
        iyy="0.843504879614984"
        iyz="-2.51058847467066E-16"
        izz="1.34196583325215" />
    </inertial>
    <visual>
      <origin
        xyz="0 0 0"
        rpy="0 0 0" />
      <geometry>
        <mesh
          filename="package://puma_model_camera/meshes/wheel_right_back_link.STL" />
      </geometry>
      <material
        name="">
        <color
          rgba="0.666666666666667 0.666666666666667 0.666666666666667 1" />
      </material>
    </visual>
    <collision>
      <origin
        xyz="0 0 0"
        rpy="0 0 0" />
      <geometry>
        <mesh
          filename="package://puma_model_camera/meshes/wheel_right_back_link.STL" />
      </geometry>
    </collision>
  </link>
  <joint
    name="wheel_right_back_joint"
    type="continuous">
    <origin
      xyz="-0.57327 -0.275 0.25"
      rpy="1.5708 0 0" />
    <parent
      link="base_link" />
    <child
      link="wheel_right_back_link" />
    <axis
      xyz="0 0 -1" />

    <dynamics
      friction="1" />
  </joint>
  <link
    name="wheel_left_back_link">
    <inertial>
      <origin
        xyz="1.11022302462516E-16 1.11022302462516E-16 0.1"
        rpy="0 0 0" />
      <mass
        value="42.8421975932662" />
      <inertia
        ixx="0.843504879614984"
        ixy="-4.06685460585996E-33"
        ixz="-3.69567293190446E-18"
        iyy="0.843504879614984"
        iyz="1.64612942139347E-17"
        izz="1.34196583325215" />
    </inertial>
    <visual>
      <origin
        xyz="0 0 0"
        rpy="0 0 0" />
      <geometry>
        <mesh
          filename="package://puma_model_camera/meshes/wheel_left_back_link.STL" />
      </geometry>
      <material
        name="">
        <color
          rgba="0.666666666666667 0.666666666666667 0.666666666666667 1" />
      </material>
    </visual>
    <collision>
      <origin
        xyz="0 0 0"
        rpy="0 0 0" />
      <geometry>
        <mesh
          filename="package://puma_model_camera/meshes/wheel_left_back_link.STL" />
      </geometry>
    </collision>
  </link>
  <joint
    name="wheel_left_back_joint"
    type="continuous">
    <origin
      xyz="-0.57327 0.275 0.25"
      rpy="-1.5708 0 0" />
    <parent
      link="base_link" />
    <child
      link="wheel_left_back_link" />
    <axis
      xyz="0 0 -1" />

    <dynamics
      friction="1" />
  </joint>
  <link
    name="base_component_link">
    <inertial>
      <origin
        xyz="-1.38777878078145E-17 -1.38777878078145E-17 0"
        rpy="0 0 0" />
      <mass
        value="26.928" />
      <inertia
        ixx="0.399432"
        ixy="1.53695574785691E-18"
        ixz="-1.04083408558608E-17"
        iyy="0.368016"
        iyz="1.04083408558608E-17"
        izz="0.5502288" />
    </inertial>
    <visual>
      <origin
        xyz="0 0 0"
        rpy="0 0 0" />
      <geometry>
        <mesh
          filename="package://puma_model_camera/meshes/base_component_link.STL" />
      </geometry>
      <material
        name="">
        <color
          rgba="1 0.752941176470588 1 1" />
      </material>
    </visual>
    <collision>
      <origin
        xyz="0 0 0"
        rpy="0 0 0" />
      <geometry>
        <mesh
          filename="package://puma_model_camera/meshes/base_component_link.STL" />
      </geometry>
    </collision>
  </link>
  <joint
    name="base_component_joint"
    type="fixed">
    <origin
      xyz="0.12673 0 0.63"
      rpy="0 0 0" />
    <parent
      link="base_link" />
    <child
      link="base_component_link" />
    <axis
      xyz="0 0 0" />
  </joint>
  <link
    name="gps_link">
    <inertial>
      <origin
        xyz="0 -1.38777878078145E-17 -0.01"
        rpy="0 0 0" />
      <mass
        value="0.1" />
      <inertia
        ixx="8.66666666666668E-05"
        ixy="7.16025184745641E-22"
        ixz="-2.70628567440132E-38"
        iyy="2.41666666666667E-05"
        iyz="-4.35487872615009E-22"
        izz="0.000104166666666667" />
    </inertial>
    <visual>
      <origin
        xyz="0 0 0"
        rpy="0 0 0" />
      <geometry>
        <mesh
          filename="package://puma_model_camera/meshes/gps_link.STL" />
      </geometry>
      <material
        name="">
        <color
          rgba="0.623529411764706 1 0.76078431372549 1" />
      </material>
    </visual>
    <collision>
      <origin
        xyz="0 0 0"
        rpy="0 0 0" />
      <geometry>
        <mesh
          filename="package://puma_model_camera/meshes/gps_link.STL" />
      </geometry>
    </collision>
  </link>
  <joint
    name="gps_joint"
    type="fixed">
    <origin
      xyz="0.27173 0 0.76"
      rpy="0 0 0" />
    <parent
      link="base_link" />
    <child
      link="gps_link" />
    <axis
      xyz="0 0 0" />
  </joint>
  <link
    name="imu1_link">
    <inertial>
      <origin
        xyz="0.01 -1.38777878078145E-17 0"
        rpy="0 0 0" />
      <mass
        value="0.1" />
      <inertia
        ixx="0.000104166666666667"
        ixy="1.2202921326777E-21"
        ixz="7.05860789378583E-22"
        iyy="8.6666666666667E-05"
        iyz="-1.12757025938493E-20"
        izz="2.41666666666667E-05" />
    </inertial>
    <visual>
      <origin
        xyz="0 0 0"
        rpy="0 0 0" />
      <geometry>
        <mesh
          filename="package://puma_model_camera/meshes/imu1_link.STL" />
      </geometry>
      <material
        name="">
        <color
          rgba="0.792156862745098 0.819607843137255 0.933333333333333 1" />
      </material>
    </visual>
    <collision>
      <origin
        xyz="0 0 0"
        rpy="0 0 0" />
      <geometry>
        <mesh
          filename="package://puma_model_camera/meshes/imu1_link.STL" />
      </geometry>
    </collision>
  </link>
  <joint
    name="imu1_link"
    type="fixed">
    <origin
      xyz="-0.74327 0 0.57"
      rpy="0 0 0" />
    <parent
      link="base_link" />
    <child
      link="imu1_link" />
    <axis
      xyz="0 0 0" />
  </joint>
  <link
    name="imu2_link">
    <inertial>
      <origin
        xyz="-0.01 0 -1.11022302462516E-16"
        rpy="0 0 0" />
      <mass
        value="0.1" />
      <inertia
        ixx="0.000104166666666667"
        ixy="-1.73472347597681E-22"
        ixz="1.75866627395253E-21"
        iyy="8.66666666666669E-05"
        iyz="2.31296463463575E-21"
        izz="2.41666666666667E-05" />
    </inertial>
    <visual>
      <origin
        xyz="0 0 0"
        rpy="0 0 0" />
      <geometry>
        <mesh
          filename="package://puma_model_camera/meshes/imu2_link.STL" />
      </geometry>
      <material
        name="">
        <color
          rgba="0.792156862745098 0.819607843137255 0.933333333333333 1" />
      </material>
    </visual>
    <collision>
      <origin
        xyz="0 0 0"
        rpy="0 0 0" />
      <geometry>
        <mesh
          filename="package://puma_model_camera/meshes/imu2_link.STL" />
      </geometry>
    </collision>
  </link>
  <joint
    name="imu2_joint"
    type="fixed">
    <origin
      xyz="0.646729916214884 0 0.37"
      rpy="0 0 0" />
    <parent
      link="base_link" />
    <child
      link="imu2_link" />
    <axis
      xyz="0 0 0" />
  </joint>
  

  <xacro:sensor_d455 parent="imu2_link" use_nominal_extrinsics="$(arg use_nominal_extrinsics)" add_plug="$(arg add_plug)"  name="$(arg name)" topics_ns="$(arg topics_ns)" publish_pointcloud="$(arg publish_pointcloud)">
    <origin xyz="0 0 0" rpy="0 0 0"/>
  </xacro:sensor_d455>

</robot>