<?xml version="1.0" encoding="utf-8"?>
<!-- This URDF was automatically created by SolidWorks to URDF Exporter! Originally created by Stephen Brawner (brawner@gmail.com) 
     Commit Version: 1.6.0-4-g7f85cfe  Build Version: 1.6.7995.38578
     For more information, please see http://wiki.ros.org/sw_urdf_exporter -->
<robot name="puma_model" xmlns:xacro="http://ros.org/wiki/xacro">
  <xacro:include filename="$(find puma_model)/urdf/puma_model.gazebo.xacro"/>
  <link
    name="base_link">
    <inertial>
      <origin
        xyz="0.0168277422445081 2.52439420492245E-07 0.369470453921975"
        rpy="0 0 0" />
      <mass
        value="154.381267641272" />
      <inertia
        ixx="3.8643546710344"
        ixy="-9.50231640652348E-07"
        ixz="1.15363830622366"
        iyy="22.232099682778"
        iyz="9.01311880648608E-06"
        izz="22.6507305397505" />
    </inertial>
    <visual>
      <origin
        xyz="0 0 0"
        rpy="0 0 0" />
      <geometry>
        <mesh
          filename="package://puma_model/meshes/base_link.STL" />
      </geometry>
      <material
        name="">
        <color
          rgba="0.988235294117647 0.737254901960784 0.517647058823529 1" />
      </material>
    </visual>
    <collision>
      <origin
        xyz="0 0 0"
        rpy="0 0 0" />
      <geometry>
        <mesh
          filename="package://puma_model/meshes/base_link.STL" />
      </geometry>
    </collision>
  </link>
  <link
    name="dir_right_link">
    <inertial>
      <origin
        xyz="-2.22044604925031E-16 -0.0294777193153578 1.11022302462516E-16"
        rpy="0 0 0" />
      <mass
        value="0.214607285846125" />
      <inertia
        ixx="0.000161787233745492"
        ixy="-1.25101536732731E-20"
        ixz="-1.72135905926183E-21"
        iyy="0.000212842937751498"
        iyz="1.18540784159886E-20"
        izz="0.000169651482672632" />
    </inertial>
    <visual>
      <origin
        xyz="0 0 0"
        rpy="0 0 0" />
      <geometry>
        <mesh
          filename="package://puma_model/meshes/dir_right_link.STL" />
      </geometry>
      <material
        name="">
        <color
          rgba="0.823529411764706 0.823529411764706 0.823529411764706 1" />
      </material>
    </visual>
    <collision>
      <origin
        xyz="0 0 0"
        rpy="0 0 0" />
      <geometry>
        <mesh
          filename="package://puma_model/meshes/dir_right_link.STL" />
      </geometry>
    </collision>
  </link>
  <joint
    name="dir_right_joint"
    type="continuous">
    <origin
      xyz="0.576729916214884 -0.337 0.265"
      rpy="0 0 0" />
    <parent
      link="base_link" />
    <child
      link="dir_right_link" />
    <axis
      xyz="0 0 1" />
  </joint>
  <link
    name="wheel_right_front_link">
    <inertial>
      <origin
        xyz="0 1.11022302462516E-16 0.07"
        rpy="0 0 0" />
      <mass
        value="33.8332405777372" />
      <inertia
        ixx="0.663166940004142"
        ixy="1.74598601904134E-32"
        ixz="4.51486827425246E-17"
        iyy="0.663166940004142"
        iyz="1.07735398960113E-17"
        izz="1.19194782788173" />
    </inertial>
    <visual>
      <origin
        xyz="0 0 0"
        rpy="0 0 0" />
      <geometry>
        <mesh
          filename="package://puma_model/meshes/wheel_right_front_link.STL" />
      </geometry>
      <material
        name="">
        <color
          rgba="1 0.752941176470588 0.752941176470588 1" />
      </material>
    </visual>
    <collision>
      <origin
        xyz="0 0 0"
        rpy="0 0 0" />
      <geometry>
        <mesh
          filename="package://puma_model/meshes/wheel_right_front_link.STL" />
      </geometry>
    </collision>
  </link>
  <joint
    name="wheel_right_front_joint"
    type="continuous">
    <origin
      xyz="0 -0.048 0"
      rpy="1.5708 0 0" />
    <parent
      link="dir_right_link" />
    <child
      link="wheel_right_front_link" />
    <axis
      xyz="0 0 -1" />
    <dynamics
      friction="1" />
  </joint>
  <link
    name="dir_left_link">
    <inertial>
      <origin
        xyz="0 0.0294777193153578 1.11022302462516E-16"
        rpy="0 0 0" />
      <mass
        value="0.214607285846125" />
      <inertia
        ixx="0.000161787233745492"
        ixy="1.85933047820183E-21"
        ixz="-2.5363205724219E-21"
        iyy="0.000212842937751498"
        iyz="3.87303577600058E-20"
        izz="0.000169651482672632" />
    </inertial>
    <visual>
      <origin
        xyz="0 0 0"
        rpy="0 0 0" />
      <geometry>
        <mesh
          filename="package://puma_model/meshes/dir_left_link.STL" />
      </geometry>
      <material
        name="">
        <color
          rgba="0.823529411764706 0.823529411764706 0.823529411764706 1" />
      </material>
    </visual>
    <collision>
      <origin
        xyz="0 0 0"
        rpy="0 0 0" />
      <geometry>
        <mesh
          filename="package://puma_model/meshes/dir_left_link.STL" />
      </geometry>
    </collision>
  </link>
  <joint
    name="dir_left_joint"
    type="continuous">
    <origin
      xyz="0.57673 0.337 0.265"
      rpy="0 0 0" />
    <parent
      link="base_link" />
    <child
      link="dir_left_link" />
    <axis
      xyz="0 0 1" />
  </joint>
  <link
    name="wheel_left_front_link">
    <inertial>
      <origin
        xyz="0 1.11022302462516E-16 0.0699999999999999"
        rpy="0 0 0" />
      <mass
        value="33.8332405777372" />
      <inertia
        ixx="0.663166940004142"
        ixy="3.62902943280336E-32"
        ixz="-3.47625364951278E-17"
        iyy="0.663166940004142"
        iyz="1.01566182105982E-18"
        izz="1.19194782788173" />
    </inertial>
    <visual>
      <origin
        xyz="0 0 0"
        rpy="0 0 0" />
      <geometry>
        <mesh
          filename="package://puma_model/meshes/wheel_left_front_link.STL" />
      </geometry>
      <material
        name="">
        <color
          rgba="1 0.752941176470588 0.752941176470588 1" />
      </material>
    </visual>
    <collision>
      <origin
        xyz="0 0 0"
        rpy="0 0 0" />
      <geometry>
        <mesh
          filename="package://puma_model/meshes/wheel_left_front_link.STL" />
      </geometry>
    </collision>
  </link>
  <joint
    name="wheel_left_front_joint"
    type="continuous">
    <origin
      xyz="0 0.048 0"
      rpy="1.5708 0 -3.1416" />
    <parent
      link="dir_left_link" />
    <child
      link="wheel_left_front_link" />
    <axis
      xyz="0 0 -1" />
    <dynamics
      friction="1" />
  </joint>
  <link
    name="wheel_right_back_link">
    <inertial>
      <origin
        xyz="0 -1.11022302462516E-16 0.1"
        rpy="0 0 0" />
      <mass
        value="42.8421975932662" />
      <inertia
        ixx="0.843504879614984"
        ixy="-2.17897005442215E-32"
        ixz="6.01287397790472E-17"
        iyy="0.843504879614984"
        iyz="-2.51058847467066E-16"
        izz="1.34196583325215" />
    </inertial>
    <visual>
      <origin
        xyz="0 0 0"
        rpy="0 0 0" />
      <geometry>
        <mesh
          filename="package://puma_model/meshes/wheel_right_back_link.STL" />
      </geometry>
      <material
        name="">
        <color
          rgba="0.666666666666667 0.666666666666667 0.666666666666667 1" />
      </material>
    </visual>
    <collision>
      <origin
        xyz="0 0 0"
        rpy="0 0 0" />
      <geometry>
        <mesh
          filename="package://puma_model/meshes/wheel_right_back_link.STL" />
      </geometry>
    </collision>
  </link>
  <joint
    name="wheel_right_back_joint"
    type="continuous">
    <origin
      xyz="-0.57327 -0.275 0.25"
      rpy="1.5708 0 0" />
    <parent
      link="base_link" />
    <child
      link="wheel_right_back_link" />
    <axis
      xyz="0 0 -1" />
    <dynamics
      friction="1" />
  </joint>
  <link
    name="wheel_left_back_link">
    <inertial>
      <origin
        xyz="1.11022302462516E-16 1.11022302462516E-16 0.1"
        rpy="0 0 0" />
      <mass
        value="42.8421975932662" />
      <inertia
        ixx="0.843504879614984"
        ixy="-4.06685460585996E-33"
        ixz="-3.69567293190446E-18"
        iyy="0.843504879614984"
        iyz="1.64612942139347E-17"
        izz="1.34196583325215" />
    </inertial>
    <visual>
      <origin
        xyz="0 0 0"
        rpy="0 0 0" />
      <geometry>
        <mesh
          filename="package://puma_model/meshes/wheel_left_back_link.STL" />
      </geometry>
      <material
        name="">
        <color
          rgba="0.666666666666667 0.666666666666667 0.666666666666667 1" />
      </material>
    </visual>
    <collision>
      <origin
        xyz="0 0 0"
        rpy="0 0 0" />
      <geometry>
        <mesh
          filename="package://puma_model/meshes/wheel_left_back_link.STL" />
      </geometry>
    </collision>
  </link>
  <joint
    name="wheel_left_back_joint"
    type="continuous">
    <origin
      xyz="-0.57327 0.275 0.25"
      rpy="-1.5708 0 0" />
    <parent
      link="base_link" />
    <child
      link="wheel_left_back_link" />
    <axis
      xyz="0 0 -1" />
    <dynamics
      friction="1" />
  </joint>
  <link
    name="base_component_link">
    <inertial>
      <origin
        xyz="-1.3878E-17 -1.3878E-17 0"
        rpy="0 0 0" />
      <mass
        value="26.928" />
      <inertia
        ixx="0.39943"
        ixy="1.537E-18"
        ixz="-1.0408E-17"
        iyy="0.36802"
        iyz="1.0408E-17"
        izz="0.55023" />
    </inertial>
    <visual>
      <origin
        xyz="0 0 0"
        rpy="0 0 0" />
      <geometry>
        <mesh
          filename="package://puma_model/meshes/base_component_link.STL" />
      </geometry>
      <material
        name="">
        <color
          rgba="1 0.75294 1 1" />
      </material>
    </visual>
    <collision>
      <origin
        xyz="0 0 0"
        rpy="0 0 0" />
      <geometry>
        <mesh
          filename="package://puma_model/meshes/base_component_link.STL" />
      </geometry>
    </collision>
  </link>
  <joint
    name="base_component_joint"
    type="fixed">
    <origin
      xyz="0.12673 0 0.63"
      rpy="0 0 0" />
    <parent
      link="base_link" />
    <child
      link="base_component_link" />
    <axis
      xyz="0 0 0" />
  </joint>
  <link
    name="gps_link">
    <inertial>
      <origin
        xyz="0 -1.3878E-17 -0.01"
        rpy="0 0 0" />
      <mass
        value="0.1" />
      <inertia
        ixx="8.6667E-05"
        ixy="7.1603E-22"
        ixz="1.084E-37"
        iyy="2.4167E-05"
        iyz="-4.3549E-22"
        izz="0.00010417" />
    </inertial>
    <visual>
      <origin
        xyz="0 0 0"
        rpy="0 0 0" />
      <geometry>
        <mesh
          filename="package://puma_model/meshes/gps_link.STL" />
      </geometry>
      <material
        name="">
        <color
          rgba="0.62353 1 0.76078 1" />
      </material>
    </visual>
    <collision>
      <origin
        xyz="0 0 0"
        rpy="0 0 0" />
      <geometry>
        <mesh
          filename="package://puma_model/meshes/gps_link.STL" />
      </geometry>
    </collision>
  </link>
  <joint
    name="gps_joint"
    type="fixed">
    <origin
      xyz="0.27173 0 0.76"
      rpy="0 0 0" />
    <parent
      link="base_link" />
    <child
      link="gps_link" />
    <axis
      xyz="0 0 0" />
  </joint>
  <link
    name="imu_link">
    <inertial>
      <origin
        xyz="5.0806E-07 -0.00019557 -0.012163"
        rpy="0 0 0" />
      <mass
        value="0.010655" />
      <inertia
        ixx="1.1671E-06"
        ixy="2.0326E-11"
        ixz="2.1164E-12"
        iyy="2.2054E-06"
        iyz="-8.1469E-10"
        izz="2.7832E-06" />
    </inertial>
    <visual>
      <origin
        xyz="0 0 0"
        rpy="0 0 0" />
      <geometry>
        <mesh
          filename="package://puma_model/meshes/imu_link.STL" />
      </geometry>
      <material
        name="">
        <color
          rgba="0.79216 0.81961 0.93333 1" />
      </material>
    </visual>
    <collision>
      <origin
        xyz="0 0 0"
        rpy="0 0 0" />
      <geometry>
        <mesh
          filename="package://puma_model/meshes/imu_link.STL" />
      </geometry>
    </collision>
  </link>
  <joint
    name="imu_joint"
    type="fixed">
    <origin
      xyz="0.21373 0.003 0.761"
      rpy="0 0 0" />
    <parent
      link="base_link" />
    <child
      link="imu_link" />
    <axis
      xyz="0 0 0" />
  </joint>
  <link
    name="camara_link">
    <inertial>
      <origin
        xyz="0.016828 2.5244E-07 0.36947"
        rpy="0 0 0" />
      <mass
        value="154.38" />
      <inertia
        ixx="3.8644"
        ixy="-9.5023E-07"
        ixz="1.1536"
        iyy="22.232"
        iyz="9.0131E-06"
        izz="22.651" />
    </inertial>
    <visual>
      <origin
        xyz="0 0 0"
        rpy="0 0 0" />
      <geometry>
        <mesh
          filename="package://puma_model/meshes/camara_link.STL" />
      </geometry>
      <material
        name="">
        <color
          rgba="0.98824 0.73725 0.51765 1" />
      </material>
    </visual>
    <collision>
      <origin
        xyz="0 0 0"
        rpy="0 0 0" />
      <geometry>
        <mesh
          filename="package://puma_model/meshes/camara_link.STL" />
      </geometry>
    </collision>
  </link>
  <joint
    name="camara_joint"
    type="fixed">
    <origin
      xyz="0.62973 0 0.36"
      rpy="0 0 0" />
    <parent
      link="base_link" />
    <child
      link="camara_link" />
    <axis
      xyz="0 0 0" />
  </joint>
  
</robot>